<?xml version="1.0" ?>
<!-- =================================================================================== -->
<!-- |    This document was autogenerated by xacro from robot_model.urdf.xacro         | -->
<!-- |    EDITING THIS FILE BY HAND IS NOT RECOMMENDED                                 | -->
<!-- =================================================================================== -->
<robot name="kit_test_robot" xmlns:xacro="http://ros.org/wiki/xacro">
  <!-- The following included files set up definitions of parts of the robot body -->
  <!--xacro:nxt_servo_v0 name="right" reflect="1"/-->
  <link name="center_servo_link">
    <inertial>
      <mass value="0.080000"/>
      <!-- center of mass (com) is defined w.r.t. link local coordinate system -->
      <origin xyz="0.0 0.0 0"/>
      <inertia ixx="0.1" ixy="0.0" ixz="0.0" iyy="1.0" iyz="0.0" izz="1.0"/>
    </inertial>
    <visual>
      <!-- visual origin is defined w.r.t. link local coordinate system -->
      <origin rpy="0 0 0" xyz="0 0 0"/>
      <geometry>
        <mesh filename="package://nxt_description/meshes/collada/sensors/interactiv_servo_motor_without_hubs.dae" scale="0.001 0.001 0.001"/>
      </geometry>
    </visual>
    <collision>
      <!-- collision origin is defined w.r.t. link local coordinate system -->
      <origin rpy="0 0 0.0" xyz="0 -0.106 -0.027"/>
      <geometry>
        <box size="0.0995 0.2695 0.1115"/>
      </geometry>
    </collision>
  </link>
  <link name="center_servo_hubs_link">
    <inertial>
      <mass value="0.000170"/>
      <!-- center of mass (com) is defined w.r.t. link local coordinate system -->
      <origin xyz="0.0 0.0 0"/>
      <inertia ixx="0.1" ixy="0.0" ixz="0.0" iyy="1.0" iyz="0.0" izz="1.0"/>
    </inertial>
    <visual>
      <!-- visual origin is defined w.r.t. link local coordinate system -->
      <origin rpy="0 0 0" xyz="0 0 0"/>
      <geometry>
        <mesh filename="package://nxt_description/meshes/collada/sensors/servo_hubs.dae" scale="0.001 0.001 0.001"/>
      </geometry>
    </visual>
    <collision>
      <!-- collision origin is defined w.r.t. link local coordinate system -->
      <origin rpy="0 0 0.0" xyz="0.02975 0 0"/>
      <geometry>
        <box size="0.0595 0.058 0.058"/>
      </geometry>
    </collision>
  </link>
  <joint name="center_servo_joint" type="continuous">
    <parent link="center_servo_link"/>
    <child link="center_servo_hubs_link"/>
    <origin rpy="0 0 0.0" xyz="0 0 0"/>
    <axis xyz="1 0 0"/>
  </joint>
  <!--xacro:nxt_servo_v0 name="left" reflect="0"/-->
  <!--xacro:nxt_brick_v0 name="nxt_brick"/-->
  <link name="c1">
    <inertial>
      <mass value="0.000275"/>
      <!-- center of mass (com) is defined w.r.t. link local coordinate system -->
      <origin xyz="0.0 0.0 0"/>
      <inertia ixx="0.1" ixy="0.0" ixz="0.0" iyy="1.0" iyz="0.0" izz="1.0"/>
    </inertial>
    <visual>
      <!-- visual origin is defined w.r.t. link local coordinate system -->
      <origin rpy="0 0 0" xyz="0 0 0"/>
      <geometry>
        <mesh filename="package://nxt_description/meshes/collada/connectors/6558.dae" scale="0.001 0.001 0.001"/>
      </geometry>
    </visual>
    <collision>
      <!-- collision origin is defined w.r.t. link local coordinate system -->
      <origin rpy="0 0 0.0" xyz="0 0 0"/>
      <geometry>
        <box size="0.060 0.016 0.0156"/>
      </geometry>
    </collision>
  </link>
  <link name="c2">
    <inertial>
      <mass value="0.000275"/>
      <!-- center of mass (com) is defined w.r.t. link local coordinate system -->
      <origin xyz="0.0 0.0 0"/>
      <inertia ixx="0.1" ixy="0.0" ixz="0.0" iyy="1.0" iyz="0.0" izz="1.0"/>
    </inertial>
    <visual>
      <!-- visual origin is defined w.r.t. link local coordinate system -->
      <origin rpy="0 0 0" xyz="0 0 0"/>
      <geometry>
        <mesh filename="package://nxt_description/meshes/collada/connectors/6558.dae" scale="0.001 0.001 0.001"/>
      </geometry>
    </visual>
    <collision>
      <!-- collision origin is defined w.r.t. link local coordinate system -->
      <origin rpy="0 0 0.0" xyz="0 0 0"/>
      <geometry>
        <box size="0.060 0.016 0.0156"/>
      </geometry>
    </collision>
  </link>
  <joint name="c1" type="fixed">
    <parent link="center_servo_link"/>
    <child link="c1"/>
    <origin rpy="-3.14159265359 0 -3.14159265359" xyz="0 -0.020 -0.040"/>
    <axis xyz="1 0 0"/>
  </joint>
  <joint name="c2" type="fixed">
    <parent link="center_servo_link"/>
    <child link="c2"/>
    <origin rpy="-3.14159265359 0 -3.14159265359" xyz="0 -0.040 -0.040"/>
    <axis xyz="1 0 0"/>
  </joint>
</robot>

